Workbook

Sheet 01_Ofertas_Originales
A1: ID | B1: → NLP | C1: Título | D1: Empresa | E1: Ubicación | F1: Fecha Publicación | G1: Portal | H1: Descripción Completa | I1: URL
A2: 1118026700 | B2: → NLP | C2: VENDEDOR DE REPUESTOS AUTOMOTOR | D2: SERVICE CARS SA | E2: Capital Federal, Buenos Aires | F2: 29-10-2025 | G2: bumeran | H2: Buscamos sumar a nuestro equipo de trabajo un REPUESTERO / VENDEDOR AUTOMOTOR CON EXPERIENCIA COMPROBABLESomos un post venta de reconocidas marcas líderes del mercado en constante expansión y buscamos el siguiente perfil: conocimiento EXCLUYENTE en mecánica y repuestos de autos, manejo básico o intermedio de paquete oficce, canales de venta online y computación en general.Buscamos una persona DINAMICA, Y CON AMBICION DE VENTAS. Que sepa trabajar en equipo y pueda manejar una excelente comunicación con las distintas áreas del taller, contribuyendo al excelente funcionamiento del mismo.Como empresa, trabajamos todos los días para darle al cliente una experiencia cálida y distinguida, buscamos un perfil que además de poseer las habilidades propias del puesto, cuente con marcada vocación de servicio y quiera sumarse a nuestro lema, que es, brindarle una experiencia de lujo al cliente en todo momento.Ofrecemos excelente clima laboral, comedor en planta, sueldo acorde al puesto, entre otros beneficios | I2: https://www.bumeran.com.ar/empleos/1118026700.html
A3: 1118026729 | B3: → NLP | C3: Responsable de Deposito | D3: Manpower | E3: Capital Federal, Buenos Aires | F3: 29-10-2025 | G3: bumeran | H3: ¡Te estamos buscando!Importante empresa internaciónal dedicada a la fabricación y comercialización de colchones, estructuras de cama, almohadas y productos de bienestar busca incorporar un/a Encargado/a de Depósito para la apertura de su nuevo local y centro de distribución en Argentina . Responsabilidades principales: • Organización integral del depósito y del nuevo punto de venta. • Control de inventarios y manejo de stocks. • Ejecución de rutinas administrativas y financieras (cierres de caja, conciliaciones bancarias, pagos). • Gestión de facturación y documentación comercial. • Coordinación y liderazgo del equipo operativo. • Entrega de mercadería y coordinación con RRHH. • Comunicación directa con directivos en Paraguay y Brasil. • Viajes ocasionales al exterior (Paraguay/Brasil) para reuniones o capacitaciones. Requisitos: • Experiencia previa en puestos similares (depósito, administración o logística). • Conocimientos sólidos en inventarios, facturación y cierres administrativos. • Habilidad para liderar y motivar equipos. • Buenas capacidades de comunicación y autogestión. • Licencia de conducir vigente (auto). • Disponibilidad para viajar. • Perfil proactivo, autogestivo, con ganas de aprender, preguntar y asumir responsabilidades. Condiciones: • Horario: lunes a viernes de 8 a 18 hs (no se trabaja feriados). Ubicación: Capital Federal, Buenos Aires. | I3: https://www.bumeran.com.ar/empleos/1118026729.html
A4: 1118027243 | B4: → NLP | C4: Abogado/a - Impuestos | D4: LAWARD Recursos Humanos para Abogados | E4: Capital Federal, Buenos Aires | F4: 30-10-2025 | G4: bumeran | H4: LAWARD seleccionará un Abogado/a para el Departamento de Impuestos de Estudio Jurídico de primera línea.Requisitos: Profesional con hasta 4 años de experiencia en Derecho Tributario, con foco en litigios y asesoramiento, incluyendo sólida gestión de casos contencioso-tributarios, manejo de casos en sede administrativa y judicial, y planificación de estrategias; Inglés, dominio oral y escrito.Se valorará a quienes cuenten con Posgrados y/o Maestrías en Derecho Tributario.Se ofrece desarrollo y crecimiento profesional así como excelente paquete de beneficios.Modalidad: Híbrida. Zona: Retiro. CABALos interesados en aplicar a la búsqueda podrán postularse enviando sin omitir remuneración bruta pretendida y promedio académico | I4: https://www.bumeran.com.ar/empleos/1118027243.html
A5: 1118027261 | B5: → NLP | C5: Supervisor de Limpieza | D5: Ceta Capital Humano | E5: San Fernando, Buenos Aires | F5: 30-10-2025 | G5: bumeran | H5: En Ceta Capital Humano nos encontramos en la búsqueda de Supervisor de Limpieza para importante frigorífico de San Fernando Zona NorteResponsabilidades: Coordinar y supervisar las tareas diarias de limpieza Planificar cronograma de trabajo y limpiezas profundas Asignar tareas y controlar el desempeño del personal a cargo Llevar control de inventario de uso de insumos Capacitar al equipo en técnicas, protocolos y seguridadRequisitos: Experiencia de 2 años en posiciones similares Experiencia en manejo de personal y control de insumos Secundario Completo Dominio de paquete office | I5: https://www.bumeran.com.ar/empleos/1118027261.html
A6: 1118027276 | B6: → NLP | C6: Ejecutivo de Cuentas SSR/SR - Presencial | D6: StaffRock IT | E6: Munro, Buenos Aires | F6: 30-10-2025 | G6: bumeran | H6: En StaffRock IT, empresa especializada en servicios de Staff Augmentation y Búsqueda y Selección de profesionales de tecnología, nos encontramos en búsqueda de un Ejecutivo de Cuentas para sumarse al equipo de una empresa del rubro eléctrico industrial.Buscamos profesionales con perfil ejecutivo y orientación a resultados, con excelentes habilidades de comunicación y autonomía, capaces de gestionar y dar seguimiento a procesos comerciales con orden y estrategia, y de comprender las necesidades del cliente para diseñar soluciones a medida.¿Cuál será tu misión?Sumarte al equipo de nuestro cliente para captar y desarrollar cuentas industriales medianas y grandes, impulsando ventas técnicas consultivas de productos y servicios críticos de energía (UPS, baterías, estabilizadores, rectificadores, grupos electrógenos) y obras eléctricas industriales y de puesta a tierra. El rol combina prospección activa (hunter) con seguimiento y expansión de cuentas (farmer), dentro de una gestión comercial estructurada con CRM (Táctica Soft).Tareas y Responsabilidades Prospección activa de clientes industriales en sectores como industria pesada, manufactura, salud, energía, laboratorios, etc. Generación de oportunidades de venta para productos y servicios técnicos. Seguimiento del pipeline comercial y actualización del CRM (Táctica Soft). Armado y presentación de propuestas técnico-comerciales. Coordinación con áreas técnicas para armado de soluciones a medida. Cumplimiento de objetivos mensuales de prospección, cotización y cierre. Mantenimiento y desarrollo de relaciones de largo plazo con cuentas claves.¿Qué skills y experiencia buscamos? Más de 3 años de experiencia comercial comprobable en venta técnica B2B Experiencia en industrias y conocimiento de sus dinámicas de compra. Perfil hunter, con energía y autonomía para salir a buscar negocio. Buen manejo de CRM (ideal si usó Táctica Soft o similar). Capacidad de redacción técnica y presentación a clientes. Conocimientos básicos de sistemas eléctricos, energía y obras eléctricas y de PAT Formación técnica (electromecánica, electrónica, electricidad, etc.). Se valorará contar con experiencia en empresas de servicios técnicos o en instalaciones/obras eléctricas, así como experiencia en la gestión de negocios a largo plazo. Nivel de inglés técnico (deseable). Preferentemente residir en zona norte (GBA) o acceso fácil a Munro.¿Qué ofrecemos? Contratación bajo Relación de Dependencia. Modalidad Full-Time y Presencial en Munro (Provincia de Buenos Aires). Excelente clima de trabajo. | I6: https://www.bumeran.com.ar/empleos/1118027276.html
A7: 1118027662 | B7: → NLP | C7: Farmacéutico/a para farmacias en Rio Cuarto | D7: Farmacity | E7: Río Cuarto, Córdoba | F7: 30-10-2025 | G7: bumeran | H7: Somos Farmacity un ecosistema de negocios compuesto por nuestra red de farmacias, Simplicity, Get The Look y The Food MarketDedicado a generar oportunidades y experiencias de bienestar que mejoran la vida de las personas a través de la salud, la belleza y la alimentación saludable.En Farmacity, valoramos la actitud protagonista de nuestros/as colaboradores/as, quienes son los verdaderos motores de nuestra organización, creando una cultura donde el bienestar, la inclusión y el crecimiento personal sean pilares fundamentales. Te invitamos a ser parte de nuestro equipo, donde podrás aplicar tus habilidades mientras aprendes y te desarrollas en un entorno laboral diverso, inclusivo y respetuoso.Estamos en búsqueda de farmacéuticos/as en Rio Cuarto que compartan nuestra visión de una atención sanitaria innovadora, dedicados y que deseen marcar la diferencia en la vida de nuestros pacientes.Si la vocación de servicio te apasiona en la farmacia, ¡esta es TU oportunidad para hacer lo que más te gusta y disfrutar cada día!🔎 ¿A quiénes buscamos? A personas que sientan la vocación de servicio con el otro. Profesionales comprometidos con la excelencia y el cuidado del paciente. A quienes siendo tal cual son, saben respetar las diferencias.📝¿Qué te proponemos? La posibilidad de unirte a una empresa que pone en el centro a sus colaboradores. No solo cuidamos la salud, sino también el bienestar de quienes forman parte de nuestro equipo, mientras seguimos creciendo y mejorando continuamente como compañía.¿Qué valoramos? Valoramos la habilidad para liderar y la capacidad de generar ideas innovadoras para estructurar equipos Dispensa de medicamentos. Control y orden de stock. Participación como agente de salud en campañas de vacunación y/o acciones destinadas a promover la salud. Garantizar la correcta trazabilidad de los medicamentos y la actualización de los libros.💡¿Qué te pediriamos? Matricula habilitada para ejercicio profesional Bloqueo de tituloLo mejor para el final: priorizamos TU Bienestar⚕️ Medicina prepaga (Swiss Medical) para vos y tu grupo familiar🙌 Pago de matrícula, colegiatura y seguro de mala praxis a cargo de la compañía🎈 Día de cumpleaños libre💌 Descuentos en nuestras sucursales y compra online de Farmacity, Get The Look, Simplicity y The Food Market📌 Descuentos corporativos en gimnasios, cines, teatros, viajes, restaurantes, spas y otros rubros.¡Postulate y empezá a vivir la #ExperienciaFarmacity! 🚀 #TuMejorVersión #DesafiateConNosotros #ExperienciaFarmacity #vocacióndeservicio#Farmaceuticos | I7: https://www.bumeran.com.ar/empleos/1118027662.html
A8: 1118027834 | B8: → NLP | C8: Vendedora Digital / Atención al Cliente | D8: metalúrgica | E8: Lomas de Zamora, Buenos Aires | F8: 30-10-2025 | G8: bumeran | H8: Vendedora Digital / Atención al Cliente OnlineResumen del PuestoEstamos buscando una Vendedora Digital / Atención al Cliente Online con un fuerte enfoque en ventas y servicio al cliente para unirse a nuestro equipo. El candidato ideal será responsable de brindar asesoramiento, seguimiento y gestión de pedidos a través de canales digitales.Responsabilidades Asesorar y atender consultas de clientes a través de medios digitales (WhatsApp, correo electrónico, redes sociales, CRM). Realizar seguimiento de presupuestos, cotizaciones y pedidos. Cargar y actualizar información en el sistema. Coordinar internamente con las áreas de logística y administración para asegurar la correcta entrega de productos. Horario de Lun a Vier de 8: 0 0 a 1 8: 0 0 Sab de 8: 0 0 a 1 3: 0 0Requisitos Experiencia en atención al cliente o ventas digitales. Manejo de herramientas informáticas. Conocimientos en sistemas CRM (deseable). Habilidades de comunicación y negociación. Orientación al cliente y capacidad de resolución de problemas. Residir en Lanus o Lomas de Zamora. | I8: https://www.bumeran.com.ar/empleos/1118027834.html
A9: 1118027941 | B9: → NLP | C9: Dibujante Tecnico | D9: Bombas y Sistemas Industriales | E9: Lomas del Mirador, Buenos Aires | F9: 30-10-2025 | G9: bumeran | H9: Empresa metalúrgica dedicada a la fabricación de repuestos, reparación y fabricación de bombas, incorpora Dibujante Técnico.Se requiere perfil Técnico con dominio de AutoCAD o herramientas de diseño similar para desempeñarse en el sector de diseño y desarrollo. Su principal responsabilidad será la realización de planos de piezas propias y el relevamiento de piezas varias y la realización de los planos correspondientes.Requisitos:Estudios: Secundario completo - Titulo Técnico Mecánico o Electromecánico.Estudiante de los primeros años de Ingeniería ( no excluyente )Conocimientos de Autocad, Solidworks 2D y 3D.Horario de trabajo: Lunes a Viernes de 8 a 16hsRemuneración pretendida. | I9: https://www.bumeran.com.ar/empleos/1118027941.html
A10: 1118028027 | B10: → NLP | C10: OPERADOR DE AUTOELEVADORES | D10: Asoko Tempo SA | E10: Villa Luzuriaga, Buenos Aires | F10: 30-10-2025 | G10: bumeran | H10: Importante Logistica busca ingresar un operador de autoelevadores con carnet habilitante para nuestra sede ubicada en Villa Luzuriaga.El ingreso es totalmente inmediato e ingresará por convenio colectivo de camioneros, categoria operador de autoelevadores.EXCLUYENTE: - Poseer carnet habilitante de conductor de autoelevadores.- ANALITICO DEL SECUNDARIO.- ANTECEDENTE PENALES ACTUALIZADOS.Turno de trabajo: TURNO TARDE (13 A 22HS) de Lunes a Viernes!Aguardamos sus postulaciones! | I10: https://www.bumeran.com.ar/empleos/1118028027.html
A11: 1118028038 | B11: → NLP | C11: Ejecutiva/o Comercial de Cuentas - GBA Norte | D11: GRUPO MASCHWITZ Hn | E11: San Isidro, Buenos Aires | F11: 30-10-2025 | G11: bumeran | H11: Ejecutiva/o Comercial de Cuentas - GBA Norte.La organización que nos encomienda esta búsqueda tiene presencia en todos los segmentos del mercado de soluciones gráficas y documentales, abarcando desde equipos de oficina de bajo/medio/alto volumen, equipos de impresión digital, grandes formatos, impresión de packaging y en diversos tipos de papel, software, etc., brindando soporte integral en lo referido a Servicio Técnico, con provisión de insumos, partes y repuestos en modalidades de venta y alquiler.El proyecto que encara en la actualidad se enfoca en el desarrollo del segmento corporativo en directa y para su red de Distribuidores a nivel nacional, buscando ampliar la presencia de sus marcas en las cuentas actuales, y creciendo en el mercado general a través de una focalizada e intensa actividad de relevamiento que permita diagnosticar y proponer soluciones racionales que generen beneficios a los clientes y permitan desplazar a la competencia. Para este fin buscamos personas con decidida vocación y formación profesional en lo comercial, orientada al trabajo relacional en las cuentas que permita contar con información clave para la preparación de propuestas competitivas.Requisitos de la posición Modalidad presencial de Lunes a Viernes. Disponibilidad para visitas a las cuentas. Trabajo por objetivos mensuales/trimestrales/anuales por línea y segmento de mercado. Capacidad de planificación del territorio asignado. Movilidad propia (no excluyente en CABA, excluyente en AMBA y Provincias). Licencia de conducir tipo B1/B2 al día. Conocimiento del mercado de equipos de oficina y gráficos, gran formato (no excluyente). Conocimiento del mercado de papel obra, coated, adhesivos, textil, etiquetas. Capacidad para orientar estrategias comerciales a los diferentes segmentos objetivo de clientes. Conocimiento de MS Office y uso de software ERP (Tango o equivalente) para carga de informes. Remuneración fija + variable en función de objetivos (comisiones) + premios + viáticos contra comprobantes.Requisitos de la persona. Estudios secundarios completos (deseables universitarios o tecnicaturas en áreas comerciales /marketing, o bien estudios de base técnica con experiencia en el trato con clientes). Experiencia comercial atendiendo cuentas en modalidad BTB de bienes o servicios. Orientación a la venta profesional en modalidad consultiva/relacional para desarrollo de cuentas en ciclo de compra. Capacidad analítica de relevamiento en cada cuenta y detección de oportunidades. Capacidad de Organización y planificación presentando informes a la Gerencia. Actitud claramente orientada a resultados. Capacidad de resiliencia y esfuerzo constante por superarse, superando obstáculos. Residencia en zonas Capital Federal o GBA Norte.La posición busca lograr objetivos cualitativos y cuantitativos a ser definidos según cada territorio en función del potencial, con acompañamiento durante los primeros meses de inducción en la parte de remuneración variable.La presente búsqueda es una oportunidad muy interesante de desarrollo profesional para quienes acepten el desafío, en un momento de expansión del negocio. Enviar CV a la dirección grupomaschwitz at gmail.com sin omitir remuneración deseada. | I11: https://www.bumeran.com.ar/empleos/1118028038.html
A12: 1118028201 | B12: → NLP | C12: 671SI Operarios ind. ALIMENTICIA c/ Tit. secundario - pres 31/10 de 10 a 1130 NUEVA Suc. SAN ISIDRO | D12: CONA CONSULTORES EN RRHH | E12: Tortuguitas, Buenos Aires | F12: 30-10-2025 | G12: bumeran | H12: CONA Consultores se encuentra en la búsqueda de OPERARIOS DE PRODUCCIÓN ALIMENTICIA con experiencia en tareas de manipulación de alimentos y producción continua. conocimiento de BPM.Importante industria ubicada en tortuguitas. DEBERÁ CONTAR CON SECUNDARIO COMPLETO Y CERTIFICADO DE ANTECEDENTES PENALES.Deberá presentarse VIERNES 31/10 de 10:00 a 11:30hs. NUEVA SUCURSAL SAN ISIDRO :EDIFICIO PANECO GOLF - LAPRIDA 3278 BLANCO OFICINA 42 - SAN ISIDROAsistir con la siguiente documentación:CV EN MANO ACTUALIZADOTITULO SECUNDARIO ORIGINAL + COPIAResidir en la zona TORTUGUITASA/ GARIN / Presentar certificado de buena conducta/ Contar con disponibilidad para turnos ROTATIVOS – (Mañana / Tarde / Noche) DISPONIBILIDAD PARA REALIZAR HS EXTRAS.Experiencia mínima de 1 año en posiciones similares.CERTIFICADO DE ANTECEDENTES PENALESResponsabilidades del puesto:Fraccionamiento y envasado de productos alimenticios.Empaque de los mismos, llenado, cierre y precintado de envases , conocimiento packaging termocontraible.Etiquetado y control de calidad de los productos envasados.cumplir con los objetivos de producción y BPMPreparación de pedidos.Mantenimiento del orden y limpieza del área de trabajo.Cumplimiento de normas de higiene y seguridad alimentaria.recepción de mercadería y materia prima.Se ofrece:Se ofrece :Trabajo full timeTM : lunes viernes de 6 a 14hs y Sab de 6 a 13hs..TT: de lunes a viernes de 13 aa 22hsPago quincenal según convenio alimentos CCT 244/94.buen clima laboral y equipo colaborativo.Ingreso eventual inmediato con posibilidad de efectivizaciónZona TORTUGUITAS¡Postula y sumate a esta gran oportunidad en la industria alimenticia.CUIDATE DE LOS AVISOS LABORALES FALSOS –En CONA siempre te postularas por plataformas de empleo directas y mails corporativos NO A PERSONAS INDIVIDUALES, nunca te pediremos que envíes fotos del DNI ni documentación personal.El empleador solo podrá solicitarle la información estrictamente necesaria para el desempeño en el trabajo que se ofrece. Ley 6471-21 GCBA | I12: https://www.bumeran.com.ar/empleos/1118028201.html
A13: 1118028376 | B13: → NLP | C13: Analista administrativo/a | D13: Randstad Argentina | E13: Capital Federal, Buenos Aires | F13: 30-10-2025 | G13: bumeran | H13: ¡Esta propuesta te puede interesar! Para importante empresa Multinacional ubicada en Nuñez, CABA, estamos en la búsqueda de un/a Analista administrativo/a. Serán sus principales tareas: Analizar y controlar los costos operativos de importación/exportación. Realizar tareas administrativas, contables, financieras de las actividades comercio internacional. Creación de ordenes de compra, solicitud de pedidos, control y seguimiento de gastos de las operaciones de comercio exterior Colaborar con equipos interdisciplinarios para optimizar la eficiencia de las operaciones comerciales (Finanzas, Contabilidad, Impuestos) Serán requisitos: Ser estudiante universitario de carreras como Administración de Empresas, Finanzas, Contador público o carreras afines. Habilidades analíticas y capacidad para interpretar datos complejos Buenas habilidades de comunicación e interpersonales Atención al detalle, precisión y enfoque en la exactitud Dominio de paquete MS Office (Principalmente Excel) Preferentemente con conocimiento del idioma Portugües. Se ofrece: Trabajo Híbrido (3 home office y 2 presencial) Medicina Prepaga Osde 210 Reintegro de gastos de conectividad Reintegro de gastos por refrigerio Capacitación continua y la oportunidad de incorporarse en una empresa muy destacada a nivel internacional Se valorarán perfiles: Con actitud proactiva y dinamismo Con buena comunicación y trabajo en equipo Con capacidad de análisis, Planificación y Organización Si consideras que reunís los requisitos para el puesto y te gustan los desafíos, no lo dudes…. ¡Postulate! Sobre Randstad En Randstad nos moviliza ayudar a las personas y a las organizaciones a desarrollar todo su potencial. Ese es el compromiso que asumimos como compañía en todo el mundo, un compromiso que nos impulsa a ir más allá para lograr que nuestros clientes y candidatos alcancen el éxito. ¿Cómo lo hacemos?, combinando nuestra pasión por las personas con el poder de la tecnología, creando experiencias más humanas, que nos permitan ser una fuente de inspiración y apoyo para quienes nos eligen. Porque estamos convencidos de que mejores personas hacen mejores. | I13: https://www.bumeran.com.ar/empleos/1118028376.html
A14: 1118028657 | B14: → NLP | C14: Recepcionista zona CABA (Eventual) | D14: Grupo Gestión | E14: Capital Federal, Buenos Aires | F14: 31-10-2025 | G14: bumeran | H14: Importante empresa se encuentra en la búsqueda de un/a recepcionista eventual.Responsabilidades del puesto: Atención personalizada a clientes y proveedores de manera presencial; telefónica o virtual Manejo de documentación Tareas administrativasHorario: lunes a viernes de 08 a 17hsZona de trabajo: Puerto MaderoSe trata de una propuesta eventual.¡Esperamos tu postulación! | I14: https://www.bumeran.com.ar/empleos/1118028657.html
... A50: 1118009703 | B50: → NLP | C50: Asesor Comercial E Commerce - Manager de redes sociales | D50: Confidencial | E50: Capital Federal, Buenos Aires | F50: 16-10-2025 | G50: bumeran | H50: Empresa de Servicios Corporativos con 30 años en el mercado está en búsqueda de un ejecutivo con experiencia en maquinaria y equipo, equipamientos de cafetería y comedores, mobiliario y decoración, equipamiento de seguridad, soluciones de automatización, refrigeración en freezer y heladeras, equipamiento de oficinas, entre otros. Atención a emprendedores, empresas, comerciantes, tiendas minoristas, cafeterías y especial atención en el segmento HORECA (restaurantes, hotelería, paradores). Tareas y funciones del puesto • Asesoramiento comercial a prospectos y emprendedores • Manejo de venta de máquinas automatizadas o tecnología de producción, especialmente en el rubro gastronómico y hotelero. • Manejo de e-commerce (Mercado Libre, Tienda web y Market Place). Creación y actualización de anuncios • Creación de diseños e iniciativas comerciales para redes sociales, crosselling y promociones • Armado de diseños personalizados para clientes o prospectos • Supervisión a la agencia de marketing digital en cuanto a funcionamiento de campañas (Meta y Google Adwords), mailing, creación de contenido y sitio web • Manejo de CRM y sistemas de gestión Manejo de herramientas y conocimientos • Paquete Office (Excel, Word, Powerpoint). • CRM Hubspot • Photoshop o afín • Canva o afín Sus Responsabilidades y Objetivos • Cumplir con los Objetivos de Ventas mensuales y anuales • Manejo de cuentas de redes sociales • Desarrollar nuevas carteras de clientes y potenciar a los clientes existentes. • Armado y gestión de publicaciones en redes sociales • Soporte en el diseño de presentaciones y material gráfico de baja y media definición • Aumentar los niveles de Facturación y participación del mercado. Amplia experiencia en • Ventas de equipamiento • Manejo de e-commerce • Google My Business y redes sociales • Manejo de objetivos de ventas Requisitos • Experiencia no menor a 3 años. Viva cerca de CABA • Sexo indistinto • Edad: Desde los 25 a 43 años Competencias • Manejo de prioridades, tiempos y seguimientos • Proactividad, entusiasmo e iniciativa • Manejo de presupuestos • Toleración a la presión del resultado y medición por objetivos • Adaptabilidad y flexibilidad • Trabajo en equipo y colaboración Ofrecemos: • Entorno laboral dinámico y motivador • Formar parte de un equipo sólido y con trayectoria en el mercado • Formación y capacitaciones constantes • Bonificaciones por desempeño y cumplimiento de objetivos Interesados • Enviar CV con pretensiones salariales • Con referencias comprobables • Horario y días: De lunes a Viernes de 8 a 17 hs • Modalidad: Presencial • Lugar de Trabajo: CAB | I50: https://www.bumeran.com.ar/empleos/1118009703.html

Sheet 02_NLP_Extraccion
A1: ID | B1: → Oferta | C1: → Match | D1: titulo_limpio | E1: provincia | F1: localidad | G1: modalidad | H1: zona_residencia_req | I1: requiere_movilidad_propia | J1: sector_empresa | K1: rubro_empresa | L1: es_tercerizado | M1: area_funcional | N1: nivel_seniority | O1: tiene_gente_cargo | P1: mision_rol | Q1: tareas_explicitas | R1: tareas_inferidas | S1: experiencia_min_anios | T1: experiencia_max_anios | U1: nivel_educativo | V1: carrera_especifica | W1: titulo_requerido | X1: skills_tecnicas_list | Y1: soft_skills_list | Z1: tecnologias_list | AA1: herramientas_list | AB1: idioma_principal | AC1: nivel_idioma_principal | AD1: jornada_laboral | AE1: tipo_contrato | AF1: salario_min | AG1: salario_max | AH1: moneda | AI1: beneficios_list | AJ1: tiene_cobertura_salud | AK1: licencia_conducir | AL1: tipo_licencia | AM1: tipo_oferta | AN1: calidad_texto | AO1: tiene_requisitos_discriminatorios | AP1: nlp_version | AQ1: nlp_confidence_score
A2: 1118026700 | B2: → Oferta | C2: → Match | D2: VENDEDOR DE REPUESTOS AUTOMOTOR | J2: Automotriz | L2: 0 | P2: vendedor automotor y repuestero | X2: ["paquete office", "canales de venta online", "computación en general"] | Y2: ["trabajo en equipo", "comunicacion"] | AI2: ["excelente clima laboral", "comedor en planta"] | AK2: 0 | AM2: demanda_real | AN2: media | AO2: 0 | AP2: 10.0.0 | AQ2: 6
A3: 1118026729 | B3: → Oferta | C3: → Match | D3: Responsable de Deposito | E3: FALSO Capital Federal | F3: FALSE | G3: presencial | J3: Manufactura/Industria | L3: 0 | M3: Operaciones/Logistica | O3: 1 | P3: Encargado/a de Depósito para la apertura de su nuevo local y centro de distribución en Argentina | Q3: [{"valor": "Organización integral del depósito y del nuevo punto de venta", "texto_original": "Organización integral del depósito y del nuevo punto de venta"}, {"valor": "Control de inventarios y manejo de stocks", "texto_original": "Control de inventarios y manejo de stocks"}, {"valor": "Ejecución de rutinas administrativas y financieras (cierres de caja, conciliaciones bancarias, pagos)", "texto_original": "Ejecución de rutinas administrativas y financieras (cierres de caja, conciliaciones bancarias, pagos)"}, {"valor": "Gestión de facturación y documentación comercial", "texto_original": "Gestión de facturación y documentación comercial"}, {"valor": "Coordinación y liderazgo del equipo operativo", "texto_original": "Coordinación y liderazgo del equipo operativo"}, {"valor": "Entrega de mercadería y coordinación con RRHH", "texto_original": "Entrega de mercadería y coordinación con RRHH"}, {"valor": "Comunicación directa con directivos en Paraguay y Brasil", "texto_original": "Comunicación directa con directivos en Paraguay y Brasil"}] | S3: 1 | X3: ["inventarios", "facturación", "cierres administrativos"] | Y3: ["liderar y motivar equipos", "buenas capacidades de comunicación", "autogestivo"] | AD3: full_time | AK3: 1 | AM3: demanda_real | AN3: alta | AO3: 0 | AP3: 10.0.0 | AQ3: 6
A4: 1118027243 | B4: → Oferta | C4: → Match | D4: Abogado/a - Impuestos | E4: TRUE | F4: TRUE | G4: TRUE | H4: TRUE | I4: TRUE | J4: TRUE | K4: TRUE | L4: TRUE | M4: TRUE | N4: junior | S4: 4 | T4: 4 | U4: universitario | W4: Abogado/a | AB4: ingles | AC4: intermedio | AD4: full_time | AI4: ["desarrollo y crecimiento profesional", "excelente paquete de beneficios"] | AK4: 0 | AM4: demanda_real | AN4: alta | AO4: 0 | AP4: 10.0.0 | AQ4: 6
A5: 1118027261 | B5: → Oferta | C5: → Match | D5: Supervisor de Limpieza | E5: Buenos Aires | F5: San Fernando | G5: presencial | J5: Manufactura/Industria | L5: 0 | M5: Operaciones/Logistica | O5: 1 | P5: Supervisar y coordinar tareas de limpieza | Q5: [{"valor": "coordinar y supervisar las tareas diarias de limpieza", "texto_original": "Coordinar y supervisar las tareas diarias de limpieza"}, {"valor": "planificar cronograma de trabajo y limpiezas profundas", "texto_original": "Planificar cronograma de trabajo y limpiezas profundas"}, {"valor": "asignar tareas y controlar el desempeño del personal a cargo", "texto_original": "Asignar tareas y controlar el desempeño del personal a cargo"}, {"valor": "llevar control de inventario de uso de insumos", "texto_original": "Llevar control de inventario de uso de insumos"}, {"valor": "capacitar al equipo en técnicas, protocolos y seguridad", "texto_original": "Capacitar al equipo en técnicas, protocolos y seguridad"}] | S5: 2 | U5: secundario | X5: ["paquete office"] | AK5: 0 | AM5: demanda_real | AN5: alta | AO5: 0 | AP5: 10.0.0 | AQ5: 6
A6: 1118027276 | B6: → Oferta | C6: → Match | D6: Ejecutivo de Cuentas SSR/SR | E6: Buenos Aires | F6: Munro | G6: presencial | H6: Preferentemente residir en zona norte (GBA) o acceso fácil a Munro | J6: Tecnologia/Software | K6: Staff Augmentation y Búsqueda y Selección | L6: 1 | M6: Ventas/Comercial | N6: semisenior | O6: 0 | P6: Captar y desarrollar cuentas industriales medianas y grandes | Q6: [{"valor": "prospección activa de clientes industriales en sectores como industria pesada, manufactura, salud, energía, laboratorios", "texto_original": "prospección activa de clientes industriales en sectores como industria pesada, manufactura, salud, energía, laboratorios"}, {"valor": "generación de oportunidades de venta para productos y servicios técnicos", "texto_original": "Generación de oportunidades de venta para productos y servicios técnicos"}, {"valor": "seguimiento del pipeline comercial y actualización del CRM (Táctica Soft)", "texto_original": "seguimiento del pipeline comercial y actualización del CRM (Táctica Soft)"}, {"valor": "armado y presentación de propuestas técnico-comerciales", "texto_original": "Armado y presentación de propuestas técnico-comerciales"}, {"valor": "coordinación con áreas técnicas para armado de soluciones a medida", "texto_original": "Coordinación con áreas técnicas para armado de soluciones a medida"}, {"valor": "cumplimiento de objetivos mensuales de prospección, cotización y cierre", "texto_original": "Cumplimiento de objetivos mensuales de prospección, cotización y cierre"}, {"valor": "mantenimiento y desarrollo de relaciones de largo plazo con cuentas claves", "texto_original": "Mantenimiento y desarrollo de relaciones de largo plazo con cuentas claves"}] | S6: 3 | U6: terciario | V6: Formación técnica (electromecánica, electrónica, electricidad) | X6: ["CRM", "Táctica Soft"] | Y6: ["comunicación", "autonomía"] | AB6: ingles | AC6: intermedio | AD6: full_time | AE6: indeterminado | AI6: ["Excelente clima de trabajo"] | AK6: 0 | AM6: demanda_real | AN6: alta | AO6: 0 | AP6: 10.0.0 | AQ6: 6
A7: 1118027662 | B7: → Oferta | C7: → Match | D7: Farmacéutico/a para farmacias en Rio Cuarto | E7: Cordoba | F7: Rio Cuarto | G7: presencial | J7: Salud/Farmaceutica | K7: farmacias | L7: 0 | M7: Salud | N7: junior | O7: 0 | P7: farmacéutico/a en Farmacity | Q7: [{"valor": "dispensa de medicamentos", "texto_original": "Dispensa de medicamentos"}, {"valor": "control y orden de stock", "texto_original": "Control y orden de stock"}, {"valor": "participación como agente de salud en campañas de vacunación", "texto_original": "Participación como agente de salud en campañas de vacunación"}] | S7: 0 | U7: universitario | W7: farmacéutico/a | Y7: ["vocación de servicio", "compromiso con la excelencia y el cuidado del paciente"] | AD7: full_time | AI7: ["Medicina prepaga (Swiss Medical) para vos y tu grupo familiar", "Pago de matrícula, colegiatura y seguro de mala praxis a cargo de la compañía", "Día de cumpleaños libre", "Descuentos en nuestras sucursales y compra online de Farmacity, Get The Look, Simplicity y The Food Market", "Descuentos corporativos en gimnasios, cines, teatros, viajes, restaurantes, spas y otros rubros"] | AJ7: 1 | AK7: 0 | AM7: demanda_real | AN7: alta | AO7: 0 | AP7: 10.0.0 | AQ7: 4
A8: 1118027834 | B8: → Oferta | C8: → Match | D8: Vendedora Digital / Atención al Cliente | E8: Buenos Aires | F8: Lanus o Lomas de Zamora | G8: presencial | H8: residir en Lanus o Lomas de Zamora | L8: 0 | M8: Ventas/Comercial | N8: junior | O8: 0 | P8: Brindar asesoramiento y seguimiento de pedidos a través de medios digitales | Q8: [{"valor": "asesorar y atender consultas", "texto_original": "Asesorar y atender consultas de clientes"}, {"valor": "realizar seguimiento de presupuestos, cotizaciones y pedidos", "texto_original": "Realizar seguimiento de presupuestos, cotizaciones y pedidos"}, {"valor": "cargar y actualizar información en el sistema", "texto_original": "Cargar y actualizar información en el sistema"}, {"valor": "coordinar internamente con áreas de logística y administración", "texto_original": "Coordinar internamente con las áreas de logística y administración para asegurar la correcta entrega de productos"}] | S8: 0 | X8: ["herramientas informáticas", "sistema CRM"] | Y8: ["comunicación", "negociación", "resolución de problemas"] | AA8: ["WhatsApp", "correo electrónico", "redes sociales"] | AD8: full_time | AK8: 0 | AM8: demanda_real | AN8: alta | AO8: 0 | AP8: 10.0.0 | AQ8: 5
A9: 1118027941 | B9: → Oferta | C9: → Match | D9: Dibujante Tecnico | G9: presencial | J9: Manufactura/Industria | K9: metalurgia | L9: 0 | M9: Operaciones/Logistica | N9: junior | O9: 0 | P9: Realización de planos de piezas propias y relevamiento de piezas varias | Q9: [{"valor": "realización de planos", "texto_original": "la realización de planos de piezas propias"}, {"valor": "relevamiento de piezas", "texto_original": "el relevamiento de piezas varias"}] | S9: 0 | U9: universitario | V9: los primeros años de Ingeniería | W9: Título Técnico Mecánico o Electromecánico | X9: ["AutoCAD", "Solidworks 2D y 3D"] | AA9: ["AutoCAD", "Solidworks 2D y 3D"] | AD9: full_time | AK9: 0 | AM9: demanda_real | AN9: media | AO9: 0 | AP9: 10.0.0 | AQ9: 5
A10: 1118028027 | B10: → Oferta | C10: → Match | D10: OPERADOR DE AUTOELEVADORES | E10: Buenos Aires | F10: Villa Luzuriaga | G10: presencial | J10: Transporte/Logistica | L10: 0 | M10: Operaciones/Logistica | N10: junior | O10: 0 | P10: Operador de autoelevadores | R10: ["manejo de autoelevadores", "trabajo en logistica"] | S10: 0 | U10: secundario | AD10: full_time | AK10: 1 | AL10: O | AM10: demanda_real | AN10: media | AO10: 0 | AP10: 10.0.0 | AQ10: 5
A11: 1118028038 | B11: → Oferta | C11: → Match | D11: Ejecutiva/o Comercial de Cuentas - GBA Norte | E11: Buenos Aires | F11: GBA Norte | G11: presencial | H11: Capital Federal o GBA Norte | I11: 1 | J11: Tecnologia/Software | K11: soluciones gráficas y documentales | L11: 0 | M11: Ventas/Comercial | N11: junior | O11: 0 | P11: Desarrollar el segmento corporativo en directa y para su red de Distribuidores a nivel nacional | Q11: [{"valor": "visitas a las cuentas", "texto_original": "Disponibilidad para visitas a las cuentas"}, {"valor": "preparación de propuestas competitivas", "texto_original": "Capacidad analítica de relevamiento en cada cuenta y detección de oportunidades"}] | R11: [{"valor": "presentar informes a la Gerencia", "texto_original": "Capacidad de Organización y planificación presentando informes a la Gerencia"}] | S11: 1 | U11: secundario | X11: ["MS Office"] | Y11: ["trabajo en equipo", "comunicacion"] | AA11: ["Tango o equivalente"] | AD11: full_time | AI11: ["viáticos contra comprobantes"] | AK11: 1 | AL11: B1 | AM11: demanda_real | AN11: alta | AO11: 0 | AP11: 10.0.0 | AQ11: 6
A12: 1118028201 | B12: → Oferta | C12: → Match | D12: 671SI Operarios ind. ALIMENTICIA c/ Tit. secundario - pres 31/10 de 10 a 1130 NUEVA Suc. SAN ISIDRO | E12: Buenos Aires | F12: San Isidro | G12: presencial | H12: Tortuguitas / GARIN | J12: Alimentacion | L12: 1 | M12: Produccion/Manufactura | N12: junior | O12: 0 | P12: Asistir en la producción y manipulación de alimentos | Q12: [{"valor": "fraccionamiento y envasado", "texto_original": "Fraccionamiento y envasado de productos alimenticios"}, {"valor": "empaque, llenado, cierre y precintado", "texto_original": "Empaque de los mismos, llenado, cierre y precintado de envases"}, {"valor": "etiquetado y control de calidad", "texto_original": "Etiquetado y control de calidad de los productos envasados"}, {"valor": "preparación de pedidos", "texto_original": "Preparación de pedidos"}, {"valor": "mantenimiento del orden y limpieza", "texto_original": "Mantenimiento del orden y limpieza del área de trabajo"}] | S12: 1 | U12: secundario | X12: ["BPM"] | AD12: full_time | AE12: eventual | AI12: ["buen clima laboral y equipo colaborativo"] | AK12: 0 | AM12: demanda_real | AN12: alta | AO12: 0 | AP12: 10.0.0 | AQ12: 6
A13: 1118028376 | B13: → Oferta | C13: → Match | D13: Analista administrativo/a | E13: CABA | F13: Nuñez | G13: hibrido | J13: Servicios Financieros | L13: 1 | M13: Administracion/Finanzas | N13: junior | O13: 0 | P13: Analizar y controlar los costos operativos de importación/exportación | Q13: [{"valor": "Realizar tareas administrativas, contables, financieras", "texto_original": "Realizar tareas administrativas, contables, financieras de las actividades comercio internacional"}, {"valor": "Colaborar con equipos interdisciplinarios para optimizar la eficiencia de las operaciones comerciales", "texto_original": "Colaborar con equipos interdisciplinarios para optimizar la eficiencia de las operaciones comerciales (Finanzas, Contabilidad, Impuestos)"}] | S13: 1 | U13: universitario | V13: universitario de carreras como Administración | X13: ["Excel"] | AA13: ["MS Office"] | AB13: ingles | AC13: intermedio | AD13: full_time | AI13: ["Medicina Prepaga Osde", "Reintegro de gastos de conectividad", "Reintegro de gastos por refrigerio"] | AJ13: 1 | AK13: 0 | AM13: demanda_real | AN13: alta | AO13: 0 | AP13: 10.0.0 | AQ13: 6
A14: 1118028657 | B14: → Oferta | C14: → Match | D14: Recepcionista | F14: Puerto Madero | G14: presencial | L14: 0 | M14: Atencion al Cliente | N14: junior | O14: 0 | P14: Atención personalizada a clientes y proveedores | Q14: [{"valor": "atención personalizada", "texto_original": "Atención personalizada a clientes y proveedores"}, {"valor": "manejo de documentación", "texto_original": "Manejo de documentación"}, {"valor": "tareas administrativas", "texto_original": "Tareas administrativas"}] | S14: 0 | AD14: full_time | AE14: eventual | AK14: 0 | AM14: demanda_real | AN14: alta | AO14: 0 | AP14: 10.0.0 | AQ14: 5
A15: 1118028681 | B15: → Oferta | C15: → Match | D15: ADMINISTRATIVA/O | E15: Buenos Aires | F15: Canning | G15: presencial | H15: Canning o zonas aledañas | I15: 1 | J15: Alimentacion | L15: 0 | M15: Administracion/Finanzas | N15: semisenior | O15: 0 | P15: Responsable del ingreso de mercadería al sistema, actualizar costos y precios de venta de los productos en el sistema, actualizar los precios de los productos en diferentes plataformas e-commerce, pago a proveedores, generar pedidos a proveedores, liquidación de sueldos | Q15: [{"valor": "ingreso de mercadería al sistema", "texto_original": "Responsable del ingreso de mercadería al sistema"}, {"valor": "actualizar costos y precios de venta en el sistema", "texto_original": "actualizar costos y precios de venta de los productos en el sistema"}, {"valor": "actualizar precios en plataformas e-commerce", "texto_original": "actualizar los precios de los productos en diferentes plataformas e-commerce"}, {"valor": "pago a proveedores", "texto_original": "pago a proveedores"}, {"valor": "generar pedidos a proveedores", "texto_original": "generar pedidos a proveedores"}, {"valor": "liquidación de sueldos", "texto_original": "liquidación de sueldos"}] | S15: 5 | X15: ["Paquete Office"] | AD15: full_time | AI15: ["excelentes condiciones de contratación"] | AK15: 0 | AM15: demanda_real | AN15: alta | AO15: 0 | AP15: 10.0.0 | AQ15: 6
A16: 1118028828 | B16: → Oferta | C16: → Match | D16: Búsqueda Laboral: Modelista – Vicente López (Florida Oeste) | E16: Buenos Aires | F16: Vicente López | G16: presencial | H16: AMBA, preferentemente cercana a Vicente López | L16: 0 | M16: Produccion/Manufactura | N16: semisenior | O16: 0 | P16: Desarrollar la moldería, prototipo y muestras de los productos de nuestras colecciones | Q16: [{"valor": "desarrollar moldería según la definición del diseño", "texto_original": "Desarrollar moldería según la definición del diseño"}, {"valor": "participar en las pruebas de calce junto al equipo de Producto", "texto_original": "Participar en las pruebas de calce junto al equipo de Producto"}, {"valor": "realizar ajustes necesarios", "texto_original": "realizando los ajustes necesarios"}, {"valor": "desarrollar progresiones de la moldería aprobada", "texto_original": "Desarrollar progresiones de la moldería aprobada"}, {"valor": "especificar avíos según género y prototipo", "texto_original": "Especificar avíos (entretelas, hilos, hombreras, etc.) según género y prototipo"}, {"valor": "realizar pruebas de comportamiento de géneros y registrar resultados", "texto_original": "Realizar pruebas de comportamiento de géneros y registrar resultados"}, {"valor": "entregar progresiones, prototipos, tablas de medidas y fichas técnicas a Producción en tiempo y forma", "texto_original": "Entregar progresiones, prototipos, tablas de medidas y fichas técnicas a Producción en tiempo y forma"}, {"valor": "colaborar en el armado del muestrario para el área Comercial", "texto_original": "Colaborar en el armado del muestrario para el área Comercial"}] | S16: 3 | U16: terciario | W16: Modelista | X16: ["Lectra"] | Y16: ["trabajo en equipo"] | AD16: full_time | AK16: 0 | AM16: demanda_real | AN16: alta | AO16: 0 | AP16: 10.0.0 | AQ16: 5
A17: 1118028833 | B17: → Oferta | C17: → Match | D17: Asesor Comercial Plan de Ahorro - Volkswagen | G17: presencial | J17: Automotriz | L17: 0 | M17: Ventas/Comercial | N17: junior | O17: 0 | P17: Asesor de ventas en concesionario automotriz | Q17: [{"valor": "optimización de los datos que se brindan para la concreción de la venta", "texto_original": "optimización de los datos que se brindan para la concreción de la venta"}, {"valor": "detección de oportunidades de nuevos negocios", "texto_original": "detección de oportunidades de nuevos negocios"}, {"valor": "cumplimiento de objetivos comerciales", "texto_original": "cumplimiento de objetivos comerciales"}] | S17: 0 | U17: secundario | Y17: ["iniciativa", "orientación al resultado", "excelencia en lo que hacemos", "orientación al cliente", "trabajo en equipo"] | AD17: full_time | AI17: ["descuento en Sport Club", "50% en todos los talleres", "15% en Repuestos", "12 cuotas S/Interés Bridgestone/Firestone 30%", "Seguros de la Caja", "Planes Adjudicados", "Descuentos en Malcriado (Shopping Tom)", "Descuentos en Samsung", "Descuentos en Bimbo"] | AK17: 0 | AM17: demanda_real | AN17: alta | AO17: 1 | AP17: 10.0.0 | AQ17: 4
A18: 1118028887 | B18: → Oferta | C18: → Match | D18: Account Executive (Hunter) | E18: Capital Federal | F18: Capital Federal | G18: hibrido | J18: Tecnologia/Software | L18: 0 | M18: Ventas/Comercial | N18: junior | O18: 0 | P18: Prospección y captación de nuevos clientes | Q18: [{"valor": "identificar oportunidades de negocio", "texto_original": "identificar oportunidades de negocio"}, {"valor": "elaborar propuestas comerciales", "texto_original": "elaborar propuestas comerciales"}, {"valor": "mantener una constante comunicación con los clientes", "texto_original": "mantener una constante comunicación con los clientes"}] | S18: 0 | T18: 2 | U18: universitario | Y18: ["mentalidad orientada a resultados", "habilidades de negociación"] | AD18: full_time | AK18: 0 | AM18: demanda_real | AN18: alta | AO18: 0 | AP18: 10.0.0 | AQ18: 5
A19: 1118028891 | B19: → Oferta | C19: → Match | D19: auxiliar contable | E19: Buenos Aires | F19: Munro | G19: hibrido | I19: 0 | L19: 0 | M19: Administracion/Finanzas | N19: junior | O19: 0 | P19: Administrativo Contable | Q19: [{"valor": "Gestión integral de caja diaria y fondos fijos", "texto_original": "Gestión integral de caja diaria y fondos fijos"}, {"valor": "Administración de cobranzas, pagos y depósitos bancarios", "texto_original": "Administración de cobranzas, pagos y depósitos bancarios"}, {"valor": "Control y registro de facturas, proveedores y padrones", "texto_original": "Control y registro de facturas, proveedores y padrones"}, {"valor": "Análisis de cuentas contables para cierres y balances", "texto_original": "Análisis de cuentas contables para cierres y balances"}, {"valor": "Emisión de pagos, notas de débito y planillas de descuentos", "texto_original": "Emisión de pagos, notas de débito y planillas de descuentos"}, {"valor": "Conciliaciones bancarias", "texto_original": "Conciliaciones bancarias"}, {"valor": "Manejo de cheques (depósito, rechazos, devoluciones)", "texto_original": "Manejo de cheques (depósito, rechazos, devoluciones)"}] | S19: 2 | T19: 2 | U19: universitario | V19: Contabilidad o un campo de | Y19: ["proactivo", "iniciativa"] | AD19: full_time | AI19: ["Bono anual por objetivos", "Celular"] | AK19: 0 | AM19: demanda_real | AN19: alta | AO19: 0 | AP19: 10.0.0 | AQ19: 6
A20: 2162667 | B20: → Oferta | C20: → Match | D20: Gerente de Operaciones | L20: 0 | M20: Operaciones/Logistica | N20: lead/manager | O20: 1 | P20: Dirigir la gestión operativa de todas las áreas de servicio | Q20: [{"valor": "Definir, implementar y supervisar estrategias operativas", "texto_original": "Definir, implementar y supervisar estrategias operativas"}, {"valor": "Dirigir equipos de coordinadores/as y supervisores/as", "texto_original": "Dirigir equipos de coordinadores/as y supervisores/as"}, {"valor": "Asegurar el cumplimiento de normas de calidad, higiene y seguridad en todas las operaciones", "texto_original": "Asegurar el cumplimiento de normas de calidad, higiene y seguridad en todas las operaciones"}, {"valor": "Monitorear indicadores clave (KPIs) de desempeño y liderar planes de mejora continua", "texto_original": "Monitorear indicadores clave (KPIs) de desempeño y liderar planes de mejora continua"}, {"valor": "Gestionar presupuestos operativos y recursos con foco en rentabilidad y sostenibilidad", "texto_original": "Gestionar presupuestos operativos y recursos con foco en rentabilidad y sostenibilidad"}, {"valor": "Mantener relaciones cercanas con clientes corporativos, promoviendo la satisfacción y fidelización", "texto_original": "Mantener relaciones cercanas con clientes corporativos, promoviendo la satisfacción y fidelización"}] | R20: [{"valor": "Impulsar proyectos innovadores en sustentabilidad y experiencia colaboradora", "texto_original": "Impulsar proyectos innovadores en sustentabilidad y experiencia colaboradora"}] | S20: 10 | U20: universitario | V20: Industrial | Y20: ["habilidades de liderazgo"] | AI20: ["Oportunidad de liderar la operación de una empresa en plena expansión", "Entorno de trabajo colaborativo, con fuerte cultura en sustentabilidad e innovación"] | AK20: 0 | AM20: demanda_real | AN20: alta | AO20: 0 | AP20: 10.0.0 | AQ20: 6
A21: 1118022146 | B21: → Oferta | C21: → Match | D21: Community manager | E21: Buenos Aires | F21: Tigre | G21: presencial | J21: Construcción | K21: Comercialización e importación de materiales para Construcción y Decoración | L21: 0 | M21: Marketing | N21: lead/manager | O21: 0 | P21: Construir y expandir las marcas del grupo fuera de Mercado Libre | Q21: [{"valor": "desarrollar e implementar iniciativas de marketing", "texto_original": "Desarrollar e implementar iniciativas de marketing"}, {"valor": "crear contenido para redes sociales", "texto_original": "Crear contenido para Instagram, Facebook y LinkedIn (producción, filmación, edición y redacción de copy)"}, {"valor": "responder mensajes en redes sociales", "texto_original": "Responder mensajes, comentarios y consultas en redes sociales"}, {"valor": "implementar campañas en Meta Ads y Google Ads", "texto_original": "Administrar campañas en Meta Ads y Google Ads"}, {"valor": "cargar y actualizar productos online", "texto_original": "Cargar y actualizar productos en TiendaNube u otras plataformas"}] | R21: [{"valor": "gestionar contactos y clientes con CRM", "texto_original": "Implementar un sistema de CRM activo para la gestión de clientes y prospectos"}, {"valor": "coordinar acciones con influencers", "texto_original": "Coordinar acciones con influencers, creadores de contenido y proveedores externos"}] | S21: 7 | U21: universitario | V21: Marketing, Comunicación, Publicidad, Branding o afines | X21: ["SEO", "Google Ads", "Meta Ads"] | Y21: ["creatividad", "atencion al detalle", "proactividad"] | Z21: ["TiendaNube", "Mercado Libre", "Shopify"] | AA21: ["CapCut", "Premiere", "Canva", "Photoshop / Illustrator"] | AD21: freelance | AI21: ["remuneracion competitiva", "oportunidad de crecer en una empresa con proyeccion regional"] | AK21: 0 | AM21: demanda_real | AN21: alta | AO21: 0 | AP21: 10.0.0 | AQ21: 5
A22: 1118025212 | B22: → Oferta | C22: → Match | D22: Representante Técnico/a Comercial | K22: agricultura | L22: 0 | M22: Ventas/Comercial | N22: junior | O22: 0 | P22: Comercialización de agro insumos y servicios | Q22: [{"valor": "asesoramiento técnico a clientes", "texto_original": "Asesoramiento técnico a clientes"}, {"valor": "desarrollo de nuevas oportunidades de negocio", "texto_original": "Desarrollo de nuevas oportunidades de negocio"}] | S22: 0 | U22: terciario | V22: carreras afines | W22: Ing. Agrónomo/a | Y22: ["vocación comercial", "orientación a resultados"] | AK22: 0 | AM22: demanda_real | AN22: media | AO22: 0 | AP22: 10.0.0 | AQ22: 5
A23: 1117984105 | B23: → Oferta | C23: → Match | D23: Venado Tuerto | E23: Santa Fe | F23: Venado Tuerto | G23: presencial | H23: Radicación en Venado Tuerto (Sta. Fé) | J23: Manufactura/Industria | K23: maquinaria agrícola | L23: 0 | M23: Ventas/Comercial | N23: lead/manager | O23: 1 | P23: Liderar equipo de ventas en concesionario oficial | R23: ["logro de objetivos comerciales", "liderazgo"] | S23: 35 | T23: 50 | U23: terciario | Y23: ["disposición para liderar en equipo", "proactivo y responsable"] | AI23: ["Buen ambiente y condiciones de trabajo"] | AK23: 0 | AM23: demanda_real | AN23: media | AO23: 1 | AP23: 10.0.0 | AQ23: 5
A24: 1117960588 | B24: → Oferta | C24: → Match | D24: Asistente de Dirección / Administrativo con experiencia en Publicidad y Medios | G24: hibrido | J24: Publicidad/Medios | L24: 0 | M24: Administracion/Finanzas | N24: junior | O24: 0 | P24: Asistir a la Dirección y coordinar tareas vinculadas a publicidad y medios | Q24: [{"valor": "Tareas administrativas generales", "texto_original": "Tareas administrativas generales"}, {"valor": "Atención telefónica y presencial de clientes y proveedores", "texto_original": "Atención telefónica y presencial de clientes y proveedores"}, {"valor": "Coordinación de llamados, correos y comunicaciones institucionales", "texto_original": "Coordinación de llamados, correos y comunicaciones institucionales"}, {"valor": "Apoyo en campañas publicitarias", "texto_original": "Apoyo en campañas publicitarias"}] | S24: 1 | X24: ["Office", "planillas", "excel avanzado"] | Y24: ["habilidades de comunicación", "atención al cliente"] | AA24: ["Office", "planillas", "excel avanzado"] | AD24: full_time | AI24: ["Excelente clima de trabajo", "posibilidades de desarrollo"] | AK24: 0 | AM24: demanda_real | AN24: alta | AO24: 0 | AP24: 10.0.0 | AQ24: 6
A25: 1118009739 | B25: → Oferta | C25: → Match | D25: Administrativa Comercio Exterior | E25: CABA | G25: hibrido | J25: Retail/Comercio | L25: 1 | M25: Administracion/Finanzas | N25: junior | O25: 0 | P25: Administrativo para área de Comex | Q25: [{"valor": "Gestión y carga de Facturación de Clientes (FC)", "texto_original": "Gestión y carga de Facturación de Clientes (FC)"}, {"valor": "Coordinación y ejecución del cierre de ciclos de pago", "texto_original": "Coordinación y ejecución del cierre de ciclos de pago"}] | S25: 0 | U25: terciario | V25: Comercio internacional | AD25: full_time | AE25: eventual | AI25: ["Cobertura médica correspondiente a convenio", "espacio de comedor"] | AJ25: 1 | AK25: 0 | AM25: demanda_real | AN25: alta | AO25: 0 | AP25: 10.0.0 | AQ25: 4
A26: 1118000814 | B26: → Oferta | C26: → Match | D26: Asistente Administrativo de Ventas | G26: presencial | L26: 0 | M26: Administracion/Finanzas | N26: junior | O26: 0 | P26: Brindar soporte administrativo y operativo al área de ventas | Q26: [{"valor": "cargar y actualizar pedidos de venta en el sistema interno", "texto_original": "Cargar y actualizar pedidos de venta en el sistema interno"}, {"valor": "elaborar reportes de ventas, márgenes, rotación y desempeño por producto o vendedor mediante Excel avanzado", "texto_original": "Elaborar reportes de ventas, márgenes, rotación y desempeño por producto o vendedor mediante Excel avanzado"}, {"valor": "controlar y coordinar entregas con el área de logística", "texto_original": "Controlar y coordinar entregas con el área de logística"}, {"valor": "mantener actualizada la base de datos de clientes, precios y promociones", "texto_original": "Mantener actualizada la base de datos de clientes, precios y promociones"}, {"valor": "realizar el seguimiento de cobranzas en coordinación con el área de administración", "texto_original": "Realizar el seguimiento de cobranzas en coordinación con el área de administración"}, {"valor": "asistir en la preparación de presentaciones comerciales e informes de gestión", "texto_original": "Asistir en la preparación de presentaciones comerciales e informes de gestión"}, {"valor": "colaborar en la implementación de acciones comerciales y campañas de venta", "texto_original": "Colaborar en la implementación de acciones comerciales y campañas de venta"}, {"valor": "gestionar documentación y archivos del área comercial", "texto_original": "Gestionar documentación y archivos del área comercial"}] | S26: 2 | U26: terciario | V26: Administración de Empresas, Comercialización o afines | X26: ["Excel avanzado"] | Y26: ["autonomía y proactividad", "orden y precisión administrativa", "orientación a resultados y al cliente interno", "capacidad analítica y atención al detalle", "trabajo en equipo y comunicación efectiva"] | Z26: ["sistemas de gestión comercial"] | AD26: full_time | AI26: ["Obra Social", "descuentos en productos", "día de cumpleaños"] | AJ26: 1 | AK26: 0 | AM26: demanda_real | AN26: alta | AO26: 0 | AP26: 10.0.0 | AQ26: 6
A27: 1118020225 | B27: → Oferta | C27: → Match | D27: Representante de atención al cliente | E27: Buenos Aires | F27: Munro | G27: hibrido | J27: Servicios Financieros | K27: servicios corporativos B2B y medios de pagos | L27: 0 | M27: Atencion al Cliente | N27: junior | O27: 0 | P27: Brindar un servicio de atención al cliente excepcional | Q27: [{"valor": "manejo de consultas, quejas y solicitudes a través de mails, llamadas telefónicas y mensajes de WhatsApp", "texto_original": "manejo de consultas, quejas y solicitudes a través de mails, llamadas telefónicas y mensajes de WhatsApp"}, {"valor": "Fidelizar al Cliente generando un vínculo duradero en el corto plazo", "texto_original": "Fidelizar al Cliente generando un vínculo duradero en el corto plazo"}, {"valor": "Detectar oportunidades de venta de otras soluciones en el periodo de implementación", "texto_original": "Detectar oportunidades de venta de otras soluciones en el periodo de implementación"}, {"valor": "Colaboración constante con otras áreas para entregar soluciones al cliente", "texto_original": "Colaboración constante con otras áreas para entregar soluciones al cliente"}, {"valor": "Proponer mejoras constantes en los procesos internos", "texto_original": "Proponer mejoras constantes en los procesos internos"}] | S27: 7 | U27: universitario | V27: Lic. en Administración, Comunicación, Comercialización y/o afines | X27: ["herramientas de CRM", "plataformas de mensajería como WhatsApp"] | Y27: ["vocación al cliente", "habilidades interpersonales y de comunicación excepcionales", "habilidades para resolver problemas"] | AA27: ["CRM", "WhatsApp"] | AB27: ingles | AC27: intermedio | AD27: full_time | AI27: ["Prepaga para grupo familiar", "Días habiles de vacaciones", "Día de cumpleaños libre", "Almuerzo Y más!"] | AJ27: 1 | AK27: 0 | AM27: demanda_real | AN27: alta | AO27: 0 | AP27: 10.0.0 | AQ27: 5
A28: 1118003709 | B28: → Oferta | C28: → Match | D28: CAJERO/ENCARGADO | E28: Buenos Aires | F28: Adrogue | G28: presencial | H28: zona o alrededores | J28: Alimentacion | L28: 0 | M28: Operaciones/Logistica | O28: 1 | P28: Manejar las transacciones diarias y coordinar al equipo del turno | Q28: [{"valor": "manejo de transacciones", "texto_original": "Manejando las transacciones diarias"}, {"valor": "arqueo de caja", "texto_original": "Realizar arqueos de caja al inicio y final del turno"}, {"valor": "atencion al cliente", "texto_original": "Brindar una óptima atención al cliente"}, {"valor": "coordinacion equipo", "texto_original": "Coordinar al equipo del turno para garantizar que las operaciones fluyan"}] | S28: 1 | AA28: ["Office", "Excel"] | AD28: full_time | AK28: 0 | AM28: demanda_real | AN28: alta | AO28: 0 | AP28: 10.0.0 | AQ28: 5
A29: 1118017586 | B29: → Oferta | C29: → Match | D29: Médica Clínica o Dermatóloga – Especialista en tratamientos estéticos inyectables | E29: Buenos Aires | F29: Quilmes | G29: presencial | J29: Salud/Farmaceutica | L29: 0 | M29: Salud | N29: semisenior | O29: 0 | P29: Realizar procedimientos inyectables y aplicar tratamientos con tecnología láser | Q29: [{"valor": "realizar procedimientos inyectables", "texto_original": "relleno de labios, ojeras, rinomodelación, Radiesse"}, {"valor": "aplicar tratamientos con tecnología láser", "texto_original": "Nordlys, CO₂"}] | S29: 1 | U29: universitario | W29: Médica Clínica o Dermatóloga | X29: ["tratamientos con tecnología láser"] | Y29: ["excelente trato interpersonal", "orientación al paciente"] | AA29: ["Ultraformer/HIFU"] | AD29: part_time | AI29: ["integración a un equipo de profesionales", "oportunidad de desarrollo profesional y crecimiento dentro de la clínica", "ambiente de trabajo profesional y ameno"] | AK29: 0 | AM29: demanda_real | AN29: alta | AO29: 0 | AP29: 10.0.0 | AQ29: 6
A30: 1118025956 | B30: → Oferta | C30: → Match | D30: Jardinero | G30: presencial | L30: 0 | M30: Operaciones/Logistica | N30: junior | O30: 0 | P30: Realizar el corte y mantenimiento del césped | Q30: [{"valor": "cuidado general de plantas y flores", "texto_original": "cuidado general de plantas y flores"}, {"valor": "mantener el orden y la limpieza de las áreas verdes", "texto_original": "mantener el orden y la limpieza de las áreas verdes"}] | S30: 1 | AD30: full_time | AK30: 1 | AM30: demanda_real | AN30: media | AO30: 0 | AP30: 10.0.0 | AQ30: 6
